Workbook

Sheet navesOri
A1: Name | B1: Ship Type | C1: Model | D1: Manufacturer | E1: Length | F1: Crew | G1: Cargo Capacity | H1: Consumables | I1: Hyperdrive Multiplier | J1: Hyperdrive Backup | K1: Speed | L1: Hull | M1: Special Features | N1: URL_data | O1: URL_image | P1: Shields | Q1: Weapons | R1: Troops | S1: Onboard Craft
A2: Builder Shuttle | B2: Landing Craft | C2: Builder Shuttle Mark 1 and Mark 2 | D2: Cygnus Spaceworks | E2: 40 meters | F2: 4 | G2: 15 metric tons (Mark 2 can hold 400 metric tons) | H2: 1 week | I2: none (Mark 2 has x1) | J2: none (Mark 2 has x10) | K2: 35 MGLT | L2: 45 RU | M2: 4 Adjustable electromagnetic lifter arms. | N2: http://insd.swcombine.com/insd/builder.htm | O2: http://insd.swcombine.com/insd/Ship_files/BUILDER.JPG
A3: TIE X3 | B3: TIE Fighters | C3: TIE/x3 Fighter | D3: Sienar Fleet Systems | E3: 7.8 meters | F3: 1 | G3: 150 kilograms | H3: 5 days | K3: 110 MGLT | L3: 14 RU | N3: http://insd.swcombine.com/insd/tiex3.htm | O3: http://insd.swcombine.com/insd/Ship_files/TIEADVA3.JPG | P3: 24 SBD | Q3: 2 Laser Cannons
A4: Star Galleon Class Frigate | B4: Medium Ships | C4: Star Galleon Class Frigate | D4: Kuat Drive Yards | E4: 298 meters | F4: 150 | G4: 100,000 metric tons | H4: 6 months | I4: x2 | J4: x15 | K4: 18 MGLT | L4: 228 RU | M4: Detachable cargo hold with hyperspace capability. | N4: http://insd.swcombine.com/insd/stargal.htm | O4: http://insd.swcombine.com/insd/Ship_files/STARGAL.JPG | P4: 320 SBD | Q4: 10 Turbolaser Cannons and 1 Concussion Missile Launcher. | R4: 300
A5: A-9 Vigilance | B5: Other Starfighters | C5: A-9 Vigilance | D5: Kuat Drive Yards | E5: 7.4 meters | F5: 1 | G5: 55 kilograms | H5: 1 day | K5: 115 MGLT | L5: 16 RU | N5: http://insd.swcombine.com/insd/a9vigil.htm | O5: http://insd.swcombine.com/insd/Ship_files/TIERPT.JPG | Q5: 2 Laser Cannons
A6: TIE Ground Targeting | B6: TIE Bombers | C6: TIE/gt Fighter | D6: Sienar Fleet Systems | E6: 6.3 meters | F6: 1 | G6: 65 kilograms | H6: 2 days | K6: 75 MGLT | L6: 9 RU | N6: http://insd.swcombine.com/insd/tiegt.htm | O6: http://insd.swcombine.com/insd/Ship_files/TIEGT.JPG | Q6: 1 Laser Cannon, 1 Concussion Missile Launcher and 1 General Purpose Launcher.
A7: Imperial Assault Transport | B7: Medium Ships | C7: Imperial Assault Transport | D7: Mesens Corporation | E7: 345 meters | F7: 275 | G7: 2,000 metric tons | H7: 2 months | I7: x0.5 | J7: x10 | K7: 26 MGLT | L7: 423 RU | N7: http://insd.swcombine.com/insd/impastrn.htm | O7: http://insd.swcombine.com/insd/Ship_files/IMPASSTR.JPG | P7: 900 SBD | Q7: 12 Heavy Turbolaser Turrets and 10 Turbolaser Cannons | R7: 2389
A8: Lambda Class T-4a Shuttle | B8: Shuttles | C8: Lambda Class T-4a Shuttle | D8: Cygnus Spaceworks | E8: 20 meters | F8: 2-4 (Depending on configuration) | G8: 0-80 metric tons (Depending on configuration) | H8: 2 months | I8: x1 | J8: x10 | K8: 67 MGLT | L8: 25 RU | M8: Adjustable stabilizer fins. | N8: http://insd.swcombine.com/insd/lamshut.htm | O8: http://insd.swcombine.com/insd/Ship_files/SHUTTLE.JPG | P8: 100 SBD | Q8: 2 Double Laser Cannons and 3 Double Blaster Cannons. | R8: 1-20 (Depending on configuration)
A9: TIE Raptor Droid | B9: TIE Fighters | C9: TIE/rpt Droid Fighter | D9: Sienar Fleet Systems / Zsinj Development Incorporated | E9: 2.1 meters | F9: 1 fully automated droid brain | H9: 2 days | K9: 90 MGLT | L9: 16 RU | N9: http://insd.swcombine.com/insd/tierpt2.htm | O9: http://insd.swcombine.com/insd/Ship_files/TIERPT1.jpg | Q9: 4 Laser Cannons and 2 Concussion Missile Launchers.
A10: TIE Experimental M2 | B10: TIE Experimental Craft | C10: TIE/e2 Fighter | D10: Sienar Fleet Systems / Imperial Department of Military Research | E10: 7 meters | F10: 1 | G10: 65 kilograms | H10: 2 days | K10: 100 MGLT | L10: 10 RU | N10: http://insd.swcombine.com/insd/tieexm2.htm | O10: http://insd.swcombine.com/insd/Ship_files/TIEEXM2.JPG | Q10: 2 Laser Cannon Turrets
A11: Gamma Class Assault Shuttle | B11: Shuttles | C11: Gamma Class Assault Shuttle | D11: Telgorn Corporation | E11: 29 meters | F11: 5 | G11: 5 metric tons | H11: 1 week | I11: x2 | J11: x18 | K11: 67 MGLT | L11: 85 RU | N11: http://insd.swcombine.com/insd/assshut.htm | O11: http://insd.swcombine.com/insd/Ship_files/ASHUTTLE.JPG | P11: 180 SBD | Q11: 4 Laser Cannon Turrets, 1 Concussion Missile Launcher and 1 Tractor Beam Projector. | R11: 40 (Zero-G Assault Stormtroopers)
A12: SFS Light Patrol Ship | B12: Patrol Craft | C12: SFS Light Patrol Ship | D12: Sienar Fleet Systems | E12: 38 meters | F12: 6 | G12: 100 metric tons | H12: 1 month | I12: x1 | J12: x10 | K12: 87 MGLT | L12: 106 RU | N12: http://insd.swcombine.com/insd/sfslps.htm | O12: http://insd.swcombine.com/insd/Ship_files/NOPIC.JPG | P12: 145 SBD | Q12: 2 Twin Laser Cannons and 3 Laser Cannon Turrets. | R12: 8
A13: Gamma Class XM-1 Missile Boat | B13: Other Starfighters | C13: Gamma Class XM-1 Mark 1 and Mark 2 Missile Boat | D13: Cygnus Spaceworks | E13: 15 meters | F13: 1 | G13: 40 kilograms | H13: 1 week | I13: x1 | K13: 122 MGLT (Speed doubles when SLAM system is used) | L13: 19 RU | M13: Sub-Light Acceleration Motor (SLAM System). | N13: http://insd.swcombine.com/insd/xmmiss.htm | O13: http://insd.swcombine.com/insd/Ship_files/MISSILE2.JPG | P13: 120 SBD | Q13: 1 Laser Cannon, 2 Concussion Missile Launchers (20 missiles each) and 2 General Purpose Launchers.
A14: Victory I Class Star Destroyer | B14: Heavy Ships | C14: Victory I Class Star Destroyer | D14: Rendili StarDrive | E14: 898 meters | F14: 5200 | G14: 8,100 metric tons | H14: 4 years | I14: x1 | J14: x15 | K14: 8 MGLT | L14: 1,520 RU | N14: http://insd.swcombine.com/insd/vsd1.htm | O14: http://insd.swcombine.com/insd/Ship_files/VSD1.JPG | P14: 3,200 SBD | Q14: 10 Quad Turbolaser Batteries, 40 Double Turbolaser Batteries, 80 Cuncussion Missile Launchers (1 warhead each) and 10 Tractor Beam Projectors. | R14: 2040 | S14: 24 TIE Series Fighters and 4 Light Transports.
A15: TIE Defender | B15: TIE Fighters | C15: TIE/df Fighter | D15: Sienar Fleet Systems | E15: 9.2 meters | F15: 1 | G15: 100 kilograms | H15: 1 week | I15: x1 | K15: 144 MGLT | L15: 14 RU | N15: http://insd.swcombine.com/insd/tiedefe.htm | O15: http://insd.swcombine.com/insd/Ship_files/TIEDEF1.JPG | P15: 100 SBD | Q15: 4 Laser Cannons, 2 Ion Cannons and 2 General Purpose Launchers.
A16: Death Star Defender | B16: Other Starfighters | C16: Death Star Defender | D16: CPG Space Products | E16: 5 meters | F16: 1 | G16: 50 kilograms | H16: 1 week | K16: 110 MGLT (90 MGLT with attack positioned wings) | L16: 7 RU | M16: Adjustable Attack Wing design. | N16: http://insd.swcombine.com/insd/dsd.htm | O16: http://insd.swcombine.com/insd/Ship_files/DSD.JPG | P16: 10 SBD | Q16: 2 Laser Cannons
A17: TIE Fire Control | B17: TIE Support Craft | C17: TIE/fc Fighter | D17: Sienar Fleet Systems | E17: 6.3 meters | F17: 1 | G17: 65 kilograms | H17: 2 days | K17: 80 MGLT | L17: 9 RU | N17: http://insd.swcombine.com/insd/tiefc.htm | O17: http://insd.swcombine.com/insd/Ship_files/TIEFC.JPG | Q17: 1 Laser Cannon
A18: TIE Droid - TIE Drone | B18: TIE Fighters | C18: TIE/d Fighter | D18: Sienar Fleet Systems | E18: 6.1 meters | F18: 1 fully automated droid brain | H18: 1 day | K18: 111 MGLT | L18: 16 RU | N18: http://insd.swcombine.com/insd/tiedroid.htm | O18: http://insd.swcombine.com/insd/Ship_files/TIEDROI2.JPG | Q18: 2 Laser Cannons
A19: Troop Drop-Ship | B19: Landing Craft | C19: MT/191 Drop-Ship | D19: Meller & Dax | E19: 52.5 meters | F19: 1 | G19: 200 metric tons | H19: 1 day | K19: 55 MGLT (100 MGLT during drop) | L19: 45 RU (90 RU during drop) | N19: http://insd.swcombine.com/insd/dropship.htm | O19: http://insd.swcombine.com/insd/Ship_files/TROOPTRN.JPG | P19: 12 SBD | Q19: 1 Light Laser Cannon | R19: 160
A20: Gamma Class ATR-6 Transport | B20: Transporters | C20: Gamma Class ATR-6 Transport | D20: Telgorn Corporation/KonGar Ship Works | E20: 44 meters | F20: 15 | G20: 400 metric tons | H20: 2 months | I20: x2 | J20: x18 | K20: 67 MGLT | L20: 142 RU | N20: http://insd.swcombine.com/insd/asstrn.htm | O20: http://insd.swcombine.com/insd/Ship_files/ASSTRN.JPG | P20: 200 SBD | Q20: 4 Double Turbolaser Turrets, 2 Medium Ion Cannons and 2 Proton Torpedo Launchers. | R20: 60
A21: Eclipse Class Star Destroyer | B21: Command Ships | C21: Eclipse Class Star Destroyer | D21: Kuat Drive Yards | E21: 16,000 meters (Prototype Lenght: 17,500 meters) | F21: 712645 | G21: 600,000 metric tons | H21: 10 years | I21: x2 | J21: x6 | K21: 6 MGLT | L21: 77,710 RU | M21: Ten Gravity Well Projectors and one Planet annihilating "superlaser" with a firing range of 31,375,000 km. | N21: http://insd.swcombine.com/insd/eclip.htm | O21: http://insd.swcombine.com/insd/Ship_files/ECLIP.JPG | P21: 136,000 SBD | Q21: 550 Heavy Turbolaser Batteries, 500 Heavy Laser Cannons, 75 Ion Cannons, 100 Tractor Beam Projectors, 10 Gravity Well Projectors and 1 Superlaser. | R21: 150000 | S21: 444 TIE Series Fighters, 72 I-7 Howlrunner Fighters, 72 Alpha Class XG-1 Star Wing Fighters, 72 A-9 Vigilance Interceptor, 36 Gamma Class XM-1 Missile Boat Fighters and 400 Light Transports.
A22: TIE Experimental M3 | B22: TIE Experimental Craft | C22: TIE/e3 Fighter | D22: Sienar Fleet Systems / Imperial Department of Military Research | E22: 6.6 meters | F22: 1 | G22: 75 kilograms | H22: 2 days | K22: 102 MGLT | L22: 16 RU | N22: http://insd.swcombine.com/insd/tieexm3.htm | O22: http://insd.swcombine.com/insd/Ship_files/TIEEXM3.JPG | Q22: 4 Laser Cannons and and 2 Concussion Missile Launchers.
A23: Dreadnaught Class Cruiser | B23: Heavy Ships | C23: Dreadnaught Class Cruiser | D23: Rendili StarDrive | E23: 600 meters | F23: 16210 | G23: 9,000 metric tons | H23: 2 years | I23: x2 | J23: x18 | K23: 12 MGLT | L23: 1,056 RU | N23: http://insd.swcombine.com/insd/dread.htm | O23: http://insd.swcombine.com/insd/Ship_files/DREADN2.JPG | P23: 1,920 SBD | Q23: 10 Turbolaser Cannons, 20 Quad Turbolaser Cannons and 10 Turbolaser Batteries. | R23: 3000 | S23: 12 TIE Series Fighters and 4 Light Transports.
A24: TIE Aggressor | B24: TIE Fighters | C24: TIE/agg Fighter | D24: Santhe / Sienar Technologies | E24: 7.8 meters | F24: 2 | G24: 150 kilograms | H24: 5 days | I24: x4 | K24: 95 MGLT | L24: 15 RU | N24: http://insd.swcombine.com/insd/tieaggre.htm | O24: http://insd.swcombine.com/insd/Ship_files/TIEAGR.JPG | P24: 21 SBD | Q24: 2 Medium Laser Cannons, 2 Concussion Missile Launchers and 1 Twin Blaster Cannon turret.
A25: Scimitar Assault Bomber | B25: TIE Bombers | C25: Scimitar Assault Bomber | D25: Sienar Fleet Systems | E25: 13.8 meters | F25: 2 | G25: 200 kilograms | H25: 2 days | K25: 90 MGLT | L25: 34 RU | N25: http://insd.swcombine.com/insd/tiescimi.htm | O25: http://insd.swcombine.com/insd/Ship_files/TIESCIMI.JPG | P25: 30 SBD | Q25: 2 Laser Cannons and 16 Concussion Missile Launchers (1 warhead each) and 1 Proton Torpedo, Orbital Mine or Thermal Detonator Launcher.
A26: T.I.E. Fighter | B26: TIE Fighters | C26: T.I.E. Fighter | D26: Republic Sienar Systems | E26: 6.3 meters | F26: 1 | G26: 45 kilograms | H26: 1 day | K26: 90 MGLT | L26: 9 RU | N26: http://insd.swcombine.com/insd/tie.htm | O26: http://insd.swcombine.com/insd/Ship_files/TIEOLD.JPG | Q26: 2 Blaster Cannons
A27: TIE Reconnaissance | B27: TIE Support Craft | C27: TIE/rc Fighter | D27: Sienar Fleet Systems | E27: 6.3 meters | F27: 1 | G27: 65 kilograms | H27: 2 days | K27: 100 MGLT | L27: 9 RU | N27: http://insd.swcombine.com/insd/tierc.htm | O27: http://insd.swcombine.com/insd/Ship_files/TIERCNEW.JPG | Q27: 1 Laser Cannon
A28: Assassin Class Corvette | B28: Medium Ships | C28: Corellian Assassin Class Corvette | D28: Corellian Engineering Corporation | E28: 153 meters | F28: 46 | G28: 500 metric tons | H28: 1 year | I28: x2 | K28: 22 MGLT | L28: 228 RU | N28: http://insd.swcombine.com/insd/assincor.htm | O28: http://insd.swcombine.com/insd/Ship_files/MCORVE.JPG | P28: 400 SBD | Q28: 2 Double Turbolaser Cannons, 4 Turbolaser Cannons and 2 Tractor Beam Projectors. | R28: 1-100 (depending upon configuration) | S28: 6 TIE Series Fighters or 2 Light Transports.
A29: Imperial Escort Carrier | B29: Heavy Ships | C29: Imperial Escort Carrier | D29: Kuat Drive Yards | E29: 501 meters | F29: 3505 | G29: 500 metric tons | H29: 9 months | I29: x1 | J29: x12 | K29: 12 MGLT | L29: 912 RU | N29: http://insd.swcombine.com/insd/esccar.htm | O29: http://insd.swcombine.com/insd/Ship_files/ESCCAR.JPG | P29: 1,600 SBD | Q29: 10 Twin Laser Cannons | R29: 800 | S29: 72 TIE Series Fighters and 6 Light Transports.
A30: Dominator Class Star Destroyer | B30: Heavy Ships | C30: Dominator Class Star Destroyer | D30: Kuat Drive Yards | E30: 1,600 meters | F30: 24724 | G30: 20,000 metric tons | H30: 4 years | I30: x1 | J30: x8 | K30: 10 MGLT | L30: 2,272 RU | M30: Four Gravity Well Projectors. | N30: http://insd.swcombine.com/insd/dominator.htm | O30: http://insd.swcombine.com/insd/Ship_files/Dominat.jpg | P30: 3,840 SBD | Q30: 40 Turbolaser Batteries, 40 Ion Cannons, 20 Laser Cannons, 6 Tractor Beam Projectors and 4 Gravity Well Projectors. | R30: 5000 | S30: 48 TIE Series Fighters, 10 Delta Class Dx-9 or Dx-9s Transports , 5 Lambda Class T-4a Shuttles, 1 Gamma Class Assault Shuttle and 1 TIE Shuttle Craft.
A31: Modular Taskforce Cruiser | B31: Heavy Ships | C31: Modular Taskforce Cruiser | D31: Tagge Industries Shipyards | E31: 1,150 meters | F31: 1,600-3,700 (varies according to mission profile) | G31: (varies according to mission profile) | H31: 6 months | I31: x3 | J31: x7 | K31: 6 MGLT | L31: 994 RU | N31: http://insd.swcombine.com/insd/taskcru.htm | O31: http://insd.swcombine.com/insd/Ship_files/Taskfor.jpg | P31: 1,920 SBD | Q31: 15 Medium Turbolasers | R31: 1-3,300 (varies according to mission profile) | S31: The hospital configuration carries 5 Lambda Class T-4a Imperial Shuttle, the survey configuration carries 6 TIE Bombers and 6 Skipray Blastboats and the observation configuration carries 12 TIE/ln Fighters.
A32: Nebulon-B Frigate | B32: Medium Ships | C32: Nebulon-B Frigate | D32: Kuat Drive Yards | E32: 300 meters | F32: 920 | G32: 6,000 metric tons | H32: 2 years | I32: x2 | J32: x12 | K32: 16 MGLT | L32: 448 RU | N32: http://insd.swcombine.com/insd/nebulonb.htm | O32: http://insd.swcombine.com/insd/Ship_files/NEBB.JPG | P32: 960 SBD | Q32: 12 Turbolaser Batteries, 12 Laser Cannons and 2 Tractor Beam Projectors. | R32: 75 | S32: 24 TIE Series Fighters and 4 Light Transports.
A33: TIE Shuttle Craft | B33: TIE Support Craft | C33: TIE/sh Shuttle | D33: Sienar Fleet Systems | E33: 7.8 meters | F33: 1 | G33: 17 + 1 metric tons (passenger pod + cargo space) | H33: 2 days | K33: 90 MGLT | L33: 28 RU | N33: http://insd.swcombine.com/insd/tieshut.htm | O33: http://insd.swcombine.com/insd/Ship_files/Tieshut.jpg | Q33: 1 Laser Cannon | R33: 2 (priority personnel)
A34: TIE Phantom | B34: TIE Fighters | C34: TIE/phn Fighter | D34: Sienar Fleet Systems / Imperial Department of Military Research | E34: 14.3 meters | F34: 2 | G34: 1 metric ton | H34: 1 week | I34: x1 | K34: 145 MGLT | L34: 20 RU | M34: Imperial Cloaking Device. | N34: http://insd.swcombine.com/insd/tiephantom.htm | O34: http://insd.swcombine.com/insd/Ship_files/Tiephan.jpg | P34: 80 SBD | Q34: 2 Medium Laser Cannons
A35: TIE Raptor | B35: TIE Fighters | C35: TIE/rpt Fighter | D35: Sienar Fleet Systems / Zsinj Development Incorporated | E35: 2.1 meters | F35: 1 | G35: 65 kilograms | H35: 2 days | K35: 90 MGLT | L35: 16 RU | N35: http://insd.swcombine.com/insd/tierpt.htm | O35: http://insd.swcombine.com/insd/Ship_files/TIERPT2.jpg | Q35: 4 Laser Cannons and 2 Concussion Missile Launchers.
A36: Delta Class Dx-9 Transport | B36: Transporters | C36: Delta Class Dx-9 Transport | D36: Telgorn Corporation | E36: 20 meters | F36: 46086 | G36: 100 metric tons | H36: 1 week | I36: x2 | J36: x18 | K36: 55 MGLT | L36: 40 RU | N36: http://insd.swcombine.com/insd/deltrn1.htm | O36: http://insd.swcombine.com/insd/Ship_files/STMTRN1.JPG | P36: 80 SBD | Q36: 8 Laser Cannons, 4 Ion Cannons and 2 Proton Torpedo Launchers. | R36: 30 (or 10 Zero-G troopers)
A37: TIE Fighter Boat | B37: TIE Fighters | C37: TIE/s Fighter | D37: Santhe / Sienar Technologies | E37: 4.3 meters | F37: 1 | G37: 45 kilograms | H37: 2 days | K37: 120 kph | L37: 9 RU | N37: http://insd.swcombine.com/insd/tiesub2.htm | O37: http://insd.swcombine.com/insd/Ship_files/TIESUB.JPG | Q37: 1 Heavy Blaster Cannon and 1 Concussion Missile Launcher.
A38: AT Barge | B38: Landing Craft | C38: AT Barge | D38: Meller & Dax | E38: 50 meters | F38: 3 | G38: 20,000 metric tons | H38: 1 day | K38: 20 MGLT | L38: 45 RU | N38: http://insd.swcombine.com/insd/atbarge.htm | O38: http://insd.swcombine.com/insd/Ship_files/ATBARGE.JPG
A39: Alpha Class XG-1 Star Wing | B39: Other Starfighters | C39: Alpha Class XG-1 Star Wing | D39: Cygnus Spaceworks | E39: 15 meters | F39: 1 | G39: 50 kilograms | H39: 1 week | I39: x1 | K39: 90 MGLT | L39: 28 RU | M39: Five wing design adjustable to various conditions. | N39: http://insd.swcombine.com/insd/gunboat.htm | O39: http://insd.swcombine.com/insd/Ship_files/GUN2.JPG | P39: 100 SBD | Q39: 2 Laser Cannons, 2 Ion Cannons and 2 Concussion Missile Launchers.
A40: TIE Interdictor | B40: TIE Bombers | C40: TIE/int Bomber | D40: Sienar Fleet Systems | E40: 7.8 meters | F40: 1 | G40: 60 metric tons (bomb bay) | H40: 2 days | K40: 80 MGLT | L40: 38 RU | N40: http://insd.swcombine.com/insd/tieintrd.htm | O40: http://insd.swcombine.com/insd/Ship_files/TIEINTRD.JPG | Q40: 2 Laser Cannons, 8 Concussion Missile Launchers and 4 Proton Torpedo, Orbital Mine or Thermal Detonator Launchers.
...

Sheet naves
A1: Manufacturer | B1: Length | C1: Cargo Capacity | D1: Hyperdrive Multiplier | E1: Speed | F1: Hull | G1: Special Features | H1: Shields | I1: Onboard Craft | J1: LASER CANNONS | K1: TURBOLASER CANNONS | L1: CONCUSSION MISSILE LAUNCHERS | M1: GENERAL PURPOSE LAUNCHERS | N1: HEAVY TURBOLASER TURRETS | O1: DOUBLE LASER CANNONS | P1: DOUBLE BLASTER CANNONS | Q1: LASER CANNON TURRETS | R1: TRACTOR BEAM PROJECTORS | S1: TWIN LASER CANNONS | T1: QUAD TURBOLASER BATTERIES | U1: DOUBLE TURBOLASER BATTERIES | V1: CUNCUSSION MISSILE LAUNCHERS | W1: ION CANNONS | X1: LIGHT LASER CANNONS | Y1: DOUBLE TURBOLASER TURRETS | Z1: MEDIUM ION CANNONS | AA1: PROTON TORPEDO LAUNCHERS | AB1: HEAVY TURBOLASER BATTERIES | AC1: HEAVY LASER CANNONS | AD1: GRAVITY WELL PROJECTORS | AE1: SUPERLASERS | AF1: QUAD TURBOLASER CANNONS | AG1: TURBOLASER BATTERIES | AH1: MEDIUM LASER CANNONS | AI1: TWIN BLASTER CANNON TURRETS | AJ1: PROTON TORPEDOS | AK1: ORBITAL MINE | AL1: THERMAL DETONATOR LAUNCHER. | AM1: BLASTER CANNONS | AN1: DOUBLE TURBOLASER CANNONS | AO1: MEDIUM TURBOLASERS | AP1: HEAVY BLASTER CANNONS | AQ1: THERMAL DETONATOR LAUNCHERS. | AR1: ION CANNON TURRETS | AS1: REPEATING BLASTER TURRETS | AT1: BUILD-IN SPACE BOMB. | AU1: HEAVY LASER CANNON TURRETS | AV1: HEAVY TURBOLASER CANNONS | AW1: TURBOLASER CANNON TURRETS | AX1: THERMAL DETONATOR LAUNCHERS | AY1: DOUBLE BLASTER CANNON TURRETS | AZ1: LASER CANNONS TURRETS | BA1: QUAD LASER CANNONS | BB1: ION CANNON BATTERIES | BC1: HEAVY TRACTORBEAM PROJECTORS | BD1: HULL-CUTTING AIRLOCKS | BE1: QUAD BLASTER CANNON | BF1: EMP CANNONS | BG1: MEDIUM BLASTER CANNONS | BH1: LIGHT TURBOLASER CANNONS | BI1: (VARIES ACCORDING TO SHIP MODEL) | BJ1: DOUBLE HEAVY LASER TURRETS | BK1: QUAD LASER CANNON TURRETS | BL1: HEAVY TURBOLASERS | BM1: MEDIUM DUAL TURBOLASERS | BN1: PROTON TORPEDO TUBES | BO1: DOUBLE LASER CANNON TURRETS | BP1: QUAD TURBOLASER TURRETS | BQ1: TURBOLASER TURRETS | BR1: Ship Type
A2: 3 | B2: 40 | C2: 15000 | D2: -1 | E2: 35 | F2: 45 | G2: 1 | H2: -1 | I2: 0 | J2: 0 | K2: 0 | L2: 0 | M2: 0 | N2: 0 | O2: 0 | P2: 0 | Q2: 0 | R2: 0 | S2: 0 | T2: 0 | U2: 0 | V2: 0 | W2: 0 | X2: 0 | Y2: 0 | Z2: 0 | AA2: 0 | AB2: 0 | AC2: 0 | AD2: 0 | AE2: 0 | AF2: 0 | AG2: 0 | AH2: 0 | AI2: 0 | AJ2: 0 | AK2: 0 | AL2: 0 | AM2: 0 | AN2: 0 | AO2: 0 | AP2: 0 | AQ2: 0 | AR2: 0 | AS2: 0 | AT2: 0 | AU2: 0 | AV2: 0 | AW2: 0 | AX2: 0 | AY2: 0 | AZ2: 0 | BA2: 0 | BB2: 0 | BC2: 0 | BD2: 0 | BE2: 0 | BF2: 0 | BG2: 0 | BH2: 0 | BI2: 0 | BJ2: 0 | BK2: 0 | BL2: 0 | BM2: 0 | BN2: 0 | BO2: 0 | BP2: 0 | BQ2: 0 | BR2: Landing Craft
A3: 18 | B3: 7.8 | C3: 150 | D3: -1 | E3: 110 | F3: 14 | G3: 0 | H3: 24 | I3: 0 | J3: 2 | K3: 0 | L3: 0 | M3: 0 | N3: 0 | O3: 0 | P3: 0 | Q3: 0 | R3: 0 | S3: 0 | T3: 0 | U3: 0 | V3: 0 | W3: 0 | X3: 0 | Y3: 0 | Z3: 0 | AA3: 0 | AB3: 0 | AC3: 0 | AD3: 0 | AE3: 0 | AF3: 0 | AG3: 0 | AH3: 0 | AI3: 0 | AJ3: 0 | AK3: 0 | AL3: 0 | AM3: 0 | AN3: 0 | AO3: 0 | AP3: 0 | AQ3: 0 | AR3: 0 | AS3: 0 | AT3: 0 | AU3: 0 | AV3: 0 | AW3: 0 | AX3: 0 | AY3: 0 | AZ3: 0 | BA3: 0 | BB3: 0 | BC3: 0 | BD3: 0 | BE3: 0 | BF3: 0 | BG3: 0 | BH3: 0 | BI3: 0 | BJ3: 0 | BK3: 0 | BL3: 0 | BM3: 0 | BN3: 0 | BO3: 0 | BP3: 0 | BQ3: 0 | BR3: TIE Fighters
A4: 8 | B4: 298 | C4: 100000000 | D4: 2 | E4: 18 | F4: 228 | G4: 1 | H4: 320 | I4: 0 | J4: 0 | K4: 10 | L4: 1 | M4: 0 | N4: 0 | O4: 0 | P4: 0 | Q4: 0 | R4: 0 | S4: 0 | T4: 0 | U4: 0 | V4: 0 | W4: 0 | X4: 0 | Y4: 0 | Z4: 0 | AA4: 0 | AB4: 0 | AC4: 0 | AD4: 0 | AE4: 0 | AF4: 0 | AG4: 0 | AH4: 0 | AI4: 0 | AJ4: 0 | AK4: 0 | AL4: 0 | AM4: 0 | AN4: 0 | AO4: 0 | AP4: 0 | AQ4: 0 | AR4: 0 | AS4: 0 | AT4: 0 | AU4: 0 | AV4: 0 | AW4: 0 | AX4: 0 | AY4: 0 | AZ4: 0 | BA4: 0 | BB4: 0 | BC4: 0 | BD4: 0 | BE4: 0 | BF4: 0 | BG4: 0 | BH4: 0 | BI4: 0 | BJ4: 0 | BK4: 0 | BL4: 0 | BM4: 0 | BN4: 0 | BO4: 0 | BP4: 0 | BQ4: 0 | BR4: Medium Ships
A5: 8 | B5: 7.4 | C5: 55 | D5: -1 | E5: 115 | F5: 16 | G5: 0 | H5: -1 | I5: 0 | J5: 2 | K5: 0 | L5: 0 | M5: 0 | N5: 0 | O5: 0 | P5: 0 | Q5: 0 | R5: 0 | S5: 0 | T5: 0 | U5: 0 | V5: 0 | W5: 0 | X5: 0 | Y5: 0 | Z5: 0 | AA5: 0 | AB5: 0 | AC5: 0 | AD5: 0 | AE5: 0 | AF5: 0 | AG5: 0 | AH5: 0 | AI5: 0 | AJ5: 0 | AK5: 0 | AL5: 0 | AM5: 0 | AN5: 0 | AO5: 0 | AP5: 0 | AQ5: 0 | AR5: 0 | AS5: 0 | AT5: 0 | AU5: 0 | AV5: 0 | AW5: 0 | AX5: 0 | AY5: 0 | AZ5: 0 | BA5: 0 | BB5: 0 | BC5: 0 | BD5: 0 | BE5: 0 | BF5: 0 | BG5: 0 | BH5: 0 | BI5: 0 | BJ5: 0 | BK5: 0 | BL5: 0 | BM5: 0 | BN5: 0 | BO5: 0 | BP5: 0 | BQ5: 0 | BR5: Other Starfighters
A6: 18 | B6: 6.3 | C6: 65 | D6: -1 | E6: 75 | F6: 9 | G6: 0 | H6: -1 | I6: 0 | J6: 1 | K6: 0 | L6: 1 | M6: 1 | N6: 0 | O6: 0 | P6: 0 | Q6: 0 | R6: 0 | S6: 0 | T6: 0 | U6: 0 | V6: 0 | W6: 0 | X6: 0 | Y6: 0 | Z6: 0 | AA6: 0 | AB6: 0 | AC6: 0 | AD6: 0 | AE6: 0 | AF6: 0 | AG6: 0 | AH6: 0 | AI6: 0 | AJ6: 0 | AK6: 0 | AL6: 0 | AM6: 0 | AN6: 0 | AO6: 0 | AP6: 0 | AQ6: 0 | AR6: 0 | AS6: 0 | AT6: 0 | AU6: 0 | AV6: 0 | AW6: 0 | AX6: 0 | AY6: 0 | AZ6: 0 | BA6: 0 | BB6: 0 | BC6: 0 | BD6: 0 | BE6: 0 | BF6: 0 | BG6: 0 | BH6: 0 | BI6: 0 | BJ6: 0 | BK6: 0 | BL6: 0 | BM6: 0 | BN6: 0 | BO6: 0 | BP6: 0 | BQ6: 0 | BR6: TIE Bombers
A7: 12 | B7: 345 | C7: 2000000 | D7: 0.5 | E7: 26 | F7: 423 | G7: 0 | H7: 900 | I7: 0 | J7: 0 | K7: 10 | L7: 0 | M7: 0 | N7: 12 | O7: 0 | P7: 0 | Q7: 0 | R7: 0 | S7: 0 | T7: 0 | U7: 0 | V7: 0 | W7: 0 | X7: 0 | Y7: 0 | Z7: 0 | AA7: 0 | AB7: 0 | AC7: 0 | AD7: 0 | AE7: 0 | AF7: 0 | AG7: 0 | AH7: 0 | AI7: 0 | AJ7: 0 | AK7: 0 | AL7: 0 | AM7: 0 | AN7: 0 | AO7: 0 | AP7: 0 | AQ7: 0 | AR7: 0 | AS7: 0 | AT7: 0 | AU7: 0 | AV7: 0 | AW7: 0 | AX7: 0 | AY7: 0 | AZ7: 0 | BA7: 0 | BB7: 0 | BC7: 0 | BD7: 0 | BE7: 0 | BF7: 0 | BG7: 0 | BH7: 0 | BI7: 0 | BJ7: 0 | BK7: 0 | BL7: 0 | BM7: 0 | BN7: 0 | BO7: 0 | BP7: 0 | BQ7: 0 | BR7: Medium Ships
A8: 3 | B8: 20 | C8: 40000 | D8: 1 | E8: 67 | F8: 25 | G8: 1 | H8: 100 | I8: 0 | J8: 0 | K8: 0 | L8: 0 | M8: 0 | N8: 0 | O8: 2 | P8: 3 | Q8: 0 | R8: 0 | S8: 0 | T8: 0 | U8: 0 | V8: 0 | W8: 0 | X8: 0 | Y8: 0 | Z8: 0 | AA8: 0 | AB8: 0 | AC8: 0 | AD8: 0 | AE8: 0 | AF8: 0 | AG8: 0 | AH8: 0 | AI8: 0 | AJ8: 0 | AK8: 0 | AL8: 0 | AM8: 0 | AN8: 0 | AO8: 0 | AP8: 0 | AQ8: 0 | AR8: 0 | AS8: 0 | AT8: 0 | AU8: 0 | AV8: 0 | AW8: 0 | AX8: 0 | AY8: 0 | AZ8: 0 | BA8: 0 | BB8: 0 | BC8: 0 | BD8: 0 | BE8: 0 | BF8: 0 | BG8: 0 | BH8: 0 | BI8: 0 | BJ8: 0 | BK8: 0 | BL8: 0 | BM8: 0 | BN8: 0 | BO8: 0 | BP8: 0 | BQ8: 0 | BR8: Shuttles
A9: 22 | B9: 2.1 | C9: -1 | D9: -1 | E9: 90 | F9: 16 | G9: 0 | H9: -1 | I9: 0 | J9: 4 | K9: 0 | L9: 2 | M9: 0 | N9: 0 | O9: 0 | P9: 0 | Q9: 0 | R9: 0 | S9: 0 | T9: 0 | U9: 0 | V9: 0 | W9: 0 | X9: 0 | Y9: 0 | Z9: 0 | AA9: 0 | AB9: 0 | AC9: 0 | AD9: 0 | AE9: 0 | AF9: 0 | AG9: 0 | AH9: 0 | AI9: 0 | AJ9: 0 | AK9: 0 | AL9: 0 | AM9: 0 | AN9: 0 | AO9: 0 | AP9: 0 | AQ9: 0 | AR9: 0 | AS9: 0 | AT9: 0 | AU9: 0 | AV9: 0 | AW9: 0 | AX9: 0 | AY9: 0 | AZ9: 0 | BA9: 0 | BB9: 0 | BC9: 0 | BD9: 0 | BE9: 0 | BF9: 0 | BG9: 0 | BH9: 0 | BI9: 0 | BJ9: 0 | BK9: 0 | BL9: 0 | BM9: 0 | BN9: 0 | BO9: 0 | BP9: 0 | BQ9: 0 | BR9: TIE Fighters
A10: 20 | B10: 7 | C10: 65 | D10: -1 | E10: 100 | F10: 10 | G10: 0 | H10: -1 | I10: 0 | J10: 0 | K10: 0 | L10: 0 | M10: 0 | N10: 0 | O10: 0 | P10: 0 | Q10: 2 | R10: 0 | S10: 0 | T10: 0 | U10: 0 | V10: 0 | W10: 0 | X10: 0 | Y10: 0 | Z10: 0 | AA10: 0 | AB10: 0 | AC10: 0 | AD10: 0 | AE10: 0 | AF10: 0 | AG10: 0 | AH10: 0 | AI10: 0 | AJ10: 0 | AK10: 0 | AL10: 0 | AM10: 0 | AN10: 0 | AO10: 0 | AP10: 0 | AQ10: 0 | AR10: 0 | AS10: 0 | AT10: 0 | AU10: 0 | AV10: 0 | AW10: 0 | AX10: 0 | AY10: 0 | AZ10: 0 | BA10: 0 | BB10: 0 | BC10: 0 | BD10: 0 | BE10: 0 | BF10: 0 | BG10: 0 | BH10: 0 | BI10: 0 | BJ10: 0 | BK10: 0 | BL10: 0 | BM10: 0 | BN10: 0 | BO10: 0 | BP10: 0 | BQ10: 0 | BR10: TIE Experimental Craft
A11: 28 | B11: 29 | C11: 5000 | D11: 2 | E11: 67 | F11: 85 | G11: 0 | H11: 180 | I11: 0 | J11: 0 | K11: 0 | L11: 1 | M11: 0 | N11: 0 | O11: 0 | P11: 0 | Q11: 4 | R11: 1 | S11: 0 | T11: 0 | U11: 0 | V11: 0 | W11: 0 | X11: 0 | Y11: 0 | Z11: 0 | AA11: 0 | AB11: 0 | AC11: 0 | AD11: 0 | AE11: 0 | AF11: 0 | AG11: 0 | AH11: 0 | AI11: 0 | AJ11: 0 | AK11: 0 | AL11: 0 | AM11: 0 | AN11: 0 | AO11: 0 | AP11: 0 | AQ11: 0 | AR11: 0 | AS11: 0 | AT11: 0 | AU11: 0 | AV11: 0 | AW11: 0 | AX11: 0 | AY11: 0 | AZ11: 0 | BA11: 0 | BB11: 0 | BC11: 0 | BD11: 0 | BE11: 0 | BF11: 0 | BG11: 0 | BH11: 0 | BI11: 0 | BJ11: 0 | BK11: 0 | BL11: 0 | BM11: 0 | BN11: 0 | BO11: 0 | BP11: 0 | BQ11: 0 | BR11: Shuttles
A12: 18 | B12: 38 | C12: 100000 | D12: 1 | E12: 87 | F12: 106 | G12: 0 | H12: 145 | I12: 0 | J12: 0 | K12: 0 | L12: 0 | M12: 0 | N12: 0 | O12: 0 | P12: 0 | Q12: 3 | R12: 0 | S12: 2 | T12: 0 | U12: 0 | V12: 0 | W12: 0 | X12: 0 | Y12: 0 | Z12: 0 | AA12: 0 | AB12: 0 | AC12: 0 | AD12: 0 | AE12: 0 | AF12: 0 | AG12: 0 | AH12: 0 | AI12: 0 | AJ12: 0 | AK12: 0 | AL12: 0 | AM12: 0 | AN12: 0 | AO12: 0 | AP12: 0 | AQ12: 0 | AR12: 0 | AS12: 0 | AT12: 0 | AU12: 0 | AV12: 0 | AW12: 0 | AX12: 0 | AY12: 0 | AZ12: 0 | BA12: 0 | BB12: 0 | BC12: 0 | BD12: 0 | BE12: 0 | BF12: 0 | BG12: 0 | BH12: 0 | BI12: 0 | BJ12: 0 | BK12: 0 | BL12: 0 | BM12: 0 | BN12: 0 | BO12: 0 | BP12: 0 | BQ12: 0 | BR12: Patrol Craft
A13: 3 | B13: 15 | C13: 40 | D13: 1 | E13: 122 | F13: 19 | G13: 1 | H13: 120 | I13: 0 | J13: 1 | K13: 0 | L13: 2 | M13: 2 | N13: 0 | O13: 0 | P13: 0 | Q13: 0 | R13: 0 | S13: 0 | T13: 0 | U13: 0 | V13: 0 | W13: 0 | X13: 0 | Y13: 0 | Z13: 0 | AA13: 0 | AB13: 0 | AC13: 0 | AD13: 0 | AE13: 0 | AF13: 0 | AG13: 0 | AH13: 0 | AI13: 0 | AJ13: 0 | AK13: 0 | AL13: 0 | AM13: 0 | AN13: 0 | AO13: 0 | AP13: 0 | AQ13: 0 | AR13: 0 | AS13: 0 | AT13: 0 | AU13: 0 | AV13: 0 | AW13: 0 | AX13: 0 | AY13: 0 | AZ13: 0 | BA13: 0 | BB13: 0 | BC13: 0 | BD13: 0 | BE13: 0 | BF13: 0 | BG13: 0 | BH13: 0 | BI13: 0 | BJ13: 0 | BK13: 0 | BL13: 0 | BM13: 0 | BN13: 0 | BO13: 0 | BP13: 0 | BQ13: 0 | BR13: Other Starfighters
... A110: 4 | B110: 20 | C110: 50000 | D110: 2 | E110: 67 | F110: 25 | G110: 1 | H110: 120 | I110: 0 | J110: 0 | K110: 0 | L110: 0 | M110: 0 | N110: 0 | O110: 0 | P110: 0 | Q110: 0 | R110: 0 | S110: 0 | T110: 0 | U110: 0 | V110: 0 | W110: 0 | X110: 0 | Y110: 0 | Z110: 0 | AA110: 0 | AB110: 0 | AC110: 0 | AD110: 0 | AE110: 0 | AF110: 0 | AG110: 0 | AH110: 2 | AI110: 0 | AJ110: 0 | AK110: 0 | AL110: 0 | AM110: 0 | AN110: 0 | AO110: 0 | AP110: 0 | AQ110: 0 | AR110: 0 | AS110: 0 | AT110: 0 | AU110: 0 | AV110: 0 | AW110: 0 | AX110: 0 | AY110: 0 | AZ110: 0 | BA110: 0 | BB110: 0 | BC110: 0 | BD110: 0 | BE110: 0 | BF110: 0 | BG110: 0 | BH110: 0 | BI110: 0 | BJ110: 0 | BK110: 0 | BL110: 0 | BM110: 0 | BN110: 0 | BO110: 0 | BP110: 0 | BQ110: 0 | BR110: Shuttles

Sheet compara
A1: =navesOri!A1 -> Name | B1: =navesOri!B1 -> Ship Type | C1: =naves!BR1 -> Ship Type | D1: =navesOri!C1 -> Model | E1: =navesOri!D1 -> Manufacturer | F1: =naves!A1 -> Manufacturer | G1: =navesOri!E1 -> Length | H1: =naves!B1 -> Length | I1: =navesOri!F1 -> Crew | J1: =navesOri!G1 -> Cargo Capacity | K1: =naves!C1 -> Cargo Capacity | L1: =navesOri!H1 -> Consumables | M1: =navesOri!I1 -> Hyperdrive Multiplier | N1: =naves!D1 -> Hyperdrive Multiplier | O1: =navesOri!J1 -> Hyperdrive Backup | P1: =navesOri!K1 -> Speed | Q1: =naves!E1 -> Speed | R1: =navesOri!L1 -> Hull | S1: =naves!F1 -> Hull | T1: =navesOri!M1 -> Special Features | U1: =naves!G1 -> Special Features | V1: =navesOri!N1 -> URL_data | W1: =navesOri!O1 -> URL_image | X1: =navesOri!P1 -> Shields | Y1: =naves!H1 -> Shields | Z1: =navesOri!R1 -> Troops | AA1: =navesOri!S1 -> Onboard Craft | AB1: =naves!I1 -> Onboard Craft | AC1: =navesOri!Q1 -> Weapons | AD1: =naves!J1 -> LASER CANNONS | AE1: =naves!K1 -> TURBOLASER CANNONS | AF1: =naves!L1 -> CONCUSSION MISSILE LAUNCHERS | AG1: =naves!M1 -> GENERAL PURPOSE LAUNCHERS | AH1: =naves!N1 -> HEAVY TURBOLASER TURRETS | AI1: =naves!O1 -> DOUBLE LASER CANNONS
A2: =navesOri!A2 -> Builder Shuttle | B2: =navesOri!B2 -> Landing Craft | C2: =naves!BR2 -> Landing Craft | D2: =navesOri!C2 -> Builder Shuttle Mark 1 and Mark 2 | E2: =navesOri!D2 -> Cygnus Spaceworks | F2: =naves!A2 -> 3 | G2: =navesOri!E2 -> 40 meters | H2: =naves!B2 -> 40 | I2: =navesOri!F2 -> 4 | J2: =navesOri!G2 -> 15 metric tons (Mark 2 can hold 400 metric tons) | K2: =naves!C2 -> 15000 | L2: =navesOri!H2 -> 1 week | M2: =navesOri!I2 -> none (Mark 2 has x1) | N2: =naves!D2 -> -1 | O2: =navesOri!J2 -> none (Mark 2 has x10) | P2: =navesOri!K2 -> 35 MGLT | Q2: =naves!E2 -> 35 | R2: =navesOri!L2 -> 45 RU | S2: =naves!F2 -> 45 | T2: =navesOri!M2 -> 4 Adjustable electromagnetic lifter arms. | U2: =naves!G2 -> 1 | V2: =navesOri!N2 -> http://insd.swcombine.com/insd/builder.htm | W2: =navesOri!O2 -> http://insd.swcombine.com/insd/Ship_files/BUILDER.JPG | X2: =navesOri!P2 | Y2: =naves!H2 -> -1 | Z2: =navesOri!R2 | AA2: =navesOri!S2 | AB2: =naves!I2 -> 0 | AC2: =navesOri!Q2 | AD2: =naves!J2 -> 0 | AE2: =naves!K2 -> 0 | AF2: =naves!L2 -> 0 | AG2: =naves!M2 -> 0
A3: =navesOri!A3 -> TIE X3 | B3: =navesOri!B3 -> TIE Fighters | C3: =naves!BR3 -> TIE Fighters | D3: =navesOri!C3 -> TIE/x3 Fighter | E3: =navesOri!D3 -> Sienar Fleet Systems | F3: =naves!A3 -> 18 | G3: =navesOri!E3 -> 7.8 meters | H3: =naves!B3 -> 7.8 | I3: =navesOri!F3 -> 1 | J3: =navesOri!G3 -> 150 kilograms | K3: =naves!C3 -> 150 | L3: =navesOri!H3 -> 5 days | M3: =navesOri!I3 | N3: =naves!D3 -> -1 | O3: =navesOri!J3 | P3: =navesOri!K3 -> 110 MGLT | Q3: =naves!E3 -> 110 | R3: =navesOri!L3 -> 14 RU | S3: =naves!F3 -> 14 | T3: =navesOri!M3 | U3: =naves!G3 -> 0 | V3: =navesOri!N3 -> http://insd.swcombine.com/insd/tiex3.htm | W3: =navesOri!O3 -> http://insd.swcombine.com/insd/Ship_files/TIEADVA3.JPG | X3: =navesOri!P3 -> 24 SBD | Y3: =naves!H3 -> 24 | Z3: =navesOri!R3 | AA3: =navesOri!S3 | AB3: =naves!I3 -> 0 | AC3: =navesOri!Q3 -> 2 Laser Cannons | AD3: =naves!J3 -> 2 | AE3: =naves!K3 -> 0 | AF3: =naves!L3 -> 0 | AG3: =naves!M3 -> 0
A4: =navesOri!A4 -> Star Galleon Class Frigate | B4: =navesOri!B4 -> Medium Ships | C4: =naves!BR4 -> Medium Ships | D4: =navesOri!C4 -> Star Galleon Class Frigate | E4: =navesOri!D4 -> Kuat Drive Yards | F4: =naves!A4 -> 8 | G4: =navesOri!E4 -> 298 meters | H4: =naves!B4 -> 298 | I4: =navesOri!F4 -> 150 | J4: =navesOri!G4 -> 100,000 metric tons | K4: =naves!C4 -> 100000000 | L4: =navesOri!H4 -> 6 months | M4: =navesOri!I4 -> x2 | N4: =naves!D4 -> 2 | O4: =navesOri!J4 -> x15 | P4: =navesOri!K4 -> 18 MGLT | Q4: =naves!E4 -> 18 | R4: =navesOri!L4 -> 228 RU | S4: =naves!F4 -> 228 | T4: =navesOri!M4 -> Detachable cargo hold with hyperspace capability. | U4: =naves!G4 -> 1 | V4: =navesOri!N4 -> http://insd.swcombine.com/insd/stargal.htm | W4: =navesOri!O4 -> http://insd.swcombine.com/insd/Ship_files/STARGAL.JPG | X4: =navesOri!P4 -> 320 SBD | Y4: =naves!H4 -> 320 | Z4: =navesOri!R4 -> 300 | AA4: =navesOri!S4 | AB4: =naves!I4 -> 0 | AC4: =navesOri!Q4 -> 10 Turbolaser Cannons and 1 Concussion Missile Launcher. | AD4: =naves!J4 -> 0 | AE4: =naves!K4 -> 10 | AF4: =naves!L4 -> 1 | AG4: =naves!M4 -> 0
A5: =navesOri!A5 -> A-9 Vigilance | B5: =navesOri!B5 -> Other Starfighters | C5: =naves!BR5 -> Other Starfighters | D5: =navesOri!C5 -> A-9 Vigilance | E5: =navesOri!D5 -> Kuat Drive Yards | F5: =naves!A5 -> 8 | G5: =navesOri!E5 -> 7.4 meters | H5: =naves!B5 -> 7.4 | I5: =navesOri!F5 -> 1 | J5: =navesOri!G5 -> 55 kilograms | K5: =naves!C5 -> 55 | L5: =navesOri!H5 -> 1 day | M5: =navesOri!I5 | N5: =naves!D5 -> -1 | O5: =navesOri!J5 | P5: =navesOri!K5 -> 115 MGLT | Q5: =naves!E5 -> 115 | R5: =navesOri!L5 -> 16 RU | S5: =naves!F5 -> 16 | T5: =navesOri!M5 | U5: =naves!G5 -> 0 | V5: =navesOri!N5 -> http://insd.swcombine.com/insd/a9vigil.htm | W5: =navesOri!O5 -> http://insd.swcombine.com/insd/Ship_files/TIERPT.JPG | X5: =navesOri!P5 | Y5: =naves!H5 -> -1 | Z5: =navesOri!R5 | AA5: =navesOri!S5 | AB5: =naves!I5 -> 0 | AC5: =navesOri!Q5 -> 2 Laser Cannons | AD5: =naves!J5 -> 2 | AE5: =naves!K5 -> 0 | AF5: =naves!L5 -> 0 | AG5: =naves!M5 -> 0
A6: =navesOri!A6 -> TIE Ground Targeting | B6: =navesOri!B6 -> TIE Bombers | C6: =naves!BR6 -> TIE Bombers | D6: =navesOri!C6 -> TIE/gt Fighter | E6: =navesOri!D6 -> Sienar Fleet Systems | F6: =naves!A6 -> 18 | G6: =navesOri!E6 -> 6.3 meters | H6: =naves!B6 -> 6.3 | I6: =navesOri!F6 -> 1 | J6: =navesOri!G6 -> 65 kilograms | K6: =naves!C6 -> 65 | L6: =navesOri!H6 -> 2 days | M6: =navesOri!I6 | N6: =naves!D6 -> -1 | O6: =navesOri!J6 | P6: =navesOri!K6 -> 75 MGLT | Q6: =naves!E6 -> 75 | R6: =navesOri!L6 -> 9 RU | S6: =naves!F6 -> 9 | T6: =navesOri!M6 | U6: =naves!G6 -> 0 | V6: =navesOri!N6 -> http://insd.swcombine.com/insd/tiegt.htm | W6: =navesOri!O6 -> http://insd.swcombine.com/insd/Ship_files/TIEGT.JPG | X6: =navesOri!P6 | Y6: =naves!H6 -> -1 | Z6: =navesOri!R6 | AA6: =navesOri!S6 | AB6: =naves!I6 -> 0 | AC6: =navesOri!Q6 -> 1 Laser Cannon, 1 Concussion Missile Launcher and 1 General Purpose Launcher. | AD6: =naves!J6 -> 1 | AE6: =naves!K6 -> 0 | AF6: =naves!L6 -> 1 | AG6: =naves!M6 -> 1
A7: =navesOri!A7 -> Imperial Assault Transport | B7: =navesOri!B7 -> Medium Ships | C7: =naves!BR7 -> Medium Ships | D7: =navesOri!C7 -> Imperial Assault Transport | E7: =navesOri!D7 -> Mesens Corporation | F7: =naves!A7 -> 12 | G7: =navesOri!E7 -> 345 meters | H7: =naves!B7 -> 345 | I7: =navesOri!F7 -> 275 | J7: =navesOri!G7 -> 2,000 metric tons | K7: =naves!C7 -> 2000000 | L7: =navesOri!H7 -> 2 months | M7: =navesOri!I7 -> x0.5 | N7: =naves!D7 -> 0.5 | O7: =navesOri!J7 -> x10 | P7: =navesOri!K7 -> 26 MGLT | Q7: =naves!E7 -> 26 | R7: =navesOri!L7 -> 423 RU | S7: =naves!F7 -> 423 | T7: =navesOri!M7 | U7: =naves!G7 -> 0 | V7: =navesOri!N7 -> http://insd.swcombine.com/insd/impastrn.htm | W7: =navesOri!O7 -> http://insd.swcombine.com/insd/Ship_files/IMPASSTR.JPG | X7: =navesOri!P7 -> 900 SBD | Y7: =naves!H7 -> 900 | Z7: =navesOri!R7 -> 2389 | AA7: =navesOri!S7 | AB7: =naves!I7 -> 0 | AC7: =navesOri!Q7 -> 12 Heavy Turbolaser Turrets and 10 Turbolaser Cannons | AD7: =naves!J7 -> 0 | AE7: =naves!K7 -> 10 | AF7: =naves!L7 -> 0 | AG7: =naves!M7 -> 0
A8: =navesOri!A8 -> Lambda Class T-4a Shuttle | B8: =navesOri!B8 -> Shuttles | C8: =naves!BR8 -> Shuttles | D8: =navesOri!C8 -> Lambda Class T-4a Shuttle | E8: =navesOri!D8 -> Cygnus Spaceworks | F8: =naves!A8 -> 3 | G8: =navesOri!E8 -> 20 meters | H8: =naves!B8 -> 20 | I8: =navesOri!F8 -> 2-4 (Depending on configuration) | J8: =navesOri!G8 -> 0-80 metric tons (Depending on configuration) | K8: =naves!C8 -> 40000 | L8: =navesOri!H8 -> 2 months | M8: =navesOri!I8 -> x1 | N8: =naves!D8 -> 1 | O8: =navesOri!J8 -> x10 | P8: =navesOri!K8 -> 67 MGLT | Q8: =naves!E8 -> 67 | R8: =navesOri!L8 -> 25 RU | S8: =naves!F8 -> 25 | T8: =navesOri!M8 -> Adjustable stabilizer fins. | U8: =naves!G8 -> 1 | V8: =navesOri!N8 -> http://insd.swcombine.com/insd/lamshut.htm | W8: =navesOri!O8 -> http://insd.swcombine.com/insd/Ship_files/SHUTTLE.JPG | X8: =navesOri!P8 -> 100 SBD | Y8: =naves!H8 -> 100 | Z8: =navesOri!R8 -> 1-20 (Depending on configuration) | AA8: =navesOri!S8 | AB8: =naves!I8 -> 0 | AC8: =navesOri!Q8 -> 2 Double Laser Cannons and 3 Double Blaster Cannons. | AD8: =naves!J8 -> 0 | AE8: =naves!K8 -> 0 | AF8: =naves!L8 -> 0 | AG8: =naves!M8 -> 0
A9: =navesOri!A9 -> TIE Raptor Droid | B9: =navesOri!B9 -> TIE Fighters | C9: =naves!BR9 -> TIE Fighters | D9: =navesOri!C9 -> TIE/rpt Droid Fighter | E9: =navesOri!D9 -> Sienar Fleet Systems / Zsinj Development Incorporated | F9: =naves!A9 -> 22 | G9: =navesOri!E9 -> 2.1 meters | H9: =naves!B9 -> 2.1 | I9: =navesOri!F9 -> 1 fully automated droid brain | J9: =navesOri!G9 | K9: =naves!C9 -> -1 | L9: =navesOri!H9 -> 2 days | M9: =navesOri!I9 | N9: =naves!D9 -> -1 | O9: =navesOri!J9 | P9: =navesOri!K9 -> 90 MGLT | Q9: =naves!E9 -> 90 | R9: =navesOri!L9 -> 16 RU | S9: =naves!F9 -> 16 | T9: =navesOri!M9 | U9: =naves!G9 -> 0 | V9: =navesOri!N9 -> http://insd.swcombine.com/insd/tierpt2.htm | W9: =navesOri!O9 -> http://insd.swcombine.com/insd/Ship_files/TIERPT1.jpg | X9: =navesOri!P9 | Y9: =naves!H9 -> -1 | Z9: =navesOri!R9 | AA9: =navesOri!S9 | AB9: =naves!I9 -> 0 | AC9: =navesOri!Q9 -> 4 Laser Cannons and 2 Concussion Missile Launchers. | AD9: =naves!J9 -> 4 | AE9: =naves!K9 -> 0 | AF9: =naves!L9 -> 2 | AG9: =naves!M9 -> 0
A10: =navesOri!A10 -> TIE Experimental M2 | B10: =navesOri!B10 -> TIE Experimental Craft | C10: =naves!BR10 -> TIE Experimental Craft | D10: =navesOri!C10 -> TIE/e2 Fighter | E10: =navesOri!D10 -> Sienar Fleet Systems / Imperial Department of Military Research | F10: =naves!A10 -> 20 | G10: =navesOri!E10 -> 7 meters | H10: =naves!B10 -> 7 | I10: =navesOri!F10 -> 1 | J10: =navesOri!G10 -> 65 kilograms | K10: =naves!C10 -> 65 | L10: =navesOri!H10 -> 2 days | M10: =navesOri!I10 | N10: =naves!D10 -> -1 | O10: =navesOri!J10 | P10: =navesOri!K10 -> 100 MGLT | Q10: =naves!E10 -> 100 | R10: =navesOri!L10 -> 10 RU | S10: =naves!F10 -> 10 | T10: =navesOri!M10 | U10: =naves!G10 -> 0 | V10: =navesOri!N10 -> http://insd.swcombine.com/insd/tieexm2.htm | W10: =navesOri!O10 -> http://insd.swcombine.com/insd/Ship_files/TIEEXM2.JPG | X10: =navesOri!P10 | Y10: =naves!H10 -> -1 | Z10: =navesOri!R10 | AA10: =navesOri!S10 | AB10: =naves!I10 -> 0 | AC10: =navesOri!Q10 -> 2 Laser Cannon Turrets | AD10: =naves!J10 -> 0 | AE10: =naves!K10 -> 0 | AF10: =naves!L10 -> 0 | AG10: =naves!M10 -> 0
A11: =navesOri!A11 -> Gamma Class Assault Shuttle | B11: =navesOri!B11 -> Shuttles | C11: =naves!BR11 -> Shuttles | D11: =navesOri!C11 -> Gamma Class Assault Shuttle | E11: =navesOri!D11 -> Telgorn Corporation | F11: =naves!A11 -> 28 | G11: =navesOri!E11 -> 29 meters | H11: =naves!B11 -> 29 | I11: =navesOri!F11 -> 5 | J11: =navesOri!G11 -> 5 metric tons | K11: =naves!C11 -> 5000 | L11: =navesOri!H11 -> 1 week | M11: =navesOri!I11 -> x2 | N11: =naves!D11 -> 2 | O11: =navesOri!J11 -> x18 | P11: =navesOri!K11 -> 67 MGLT | Q11: =naves!E11 -> 67 | R11: =navesOri!L11 -> 85 RU | S11: =naves!F11 -> 85 | T11: =navesOri!M11 | U11: =naves!G11 -> 0 | V11: =navesOri!N11 -> http://insd.swcombine.com/insd/assshut.htm | W11: =navesOri!O11 -> http://insd.swcombine.com/insd/Ship_files/ASHUTTLE.JPG | X11: =navesOri!P11 -> 180 SBD | Y11: =naves!H11 -> 180 | Z11: =navesOri!R11 -> 40 (Zero-G Assault Stormtroopers) | AA11: =navesOri!S11 | AB11: =naves!I11 -> 0 | AC11: =navesOri!Q11 -> 4 Laser Cannon Turrets, 1 Concussion Missile Launcher and 1 Tractor Beam Projector. | AD11: =naves!J11 -> 0 | AE11: =naves!K11 -> 0 | AF11: =naves!L11 -> 1 | AG11: =naves!M11 -> 0
A12: =navesOri!A12 -> SFS Light Patrol Ship | B12: =navesOri!B12 -> Patrol Craft | C12: =naves!BR12 -> Patrol Craft | D12: =navesOri!C12 -> SFS Light Patrol Ship | E12: =navesOri!D12 -> Sienar Fleet Systems | F12: =naves!A12 -> 18 | G12: =navesOri!E12 -> 38 meters | H12: =naves!B12 -> 38 | I12: =navesOri!F12 -> 6 | J12: =navesOri!G12 -> 100 metric tons | K12: =naves!C12 -> 100000 | L12: =navesOri!H12 -> 1 month | M12: =navesOri!I12 -> x1 | N12: =naves!D12 -> 1 | O12: =navesOri!J12 -> x10 | P12: =navesOri!K12 -> 87 MGLT | Q12: =naves!E12 -> 87 | R12: =navesOri!L12 -> 106 RU | S12: =naves!F12 -> 106 | T12: =navesOri!M12 | U12: =naves!G12 -> 0 | V12: =navesOri!N12 -> http://insd.swcombine.com/insd/sfslps.htm | W12: =navesOri!O12 -> http://insd.swcombine.com/insd/Ship_files/NOPIC.JPG | X12: =navesOri!P12 -> 145 SBD | Y12: =naves!H12 -> 145 | Z12: =navesOri!R12 -> 8 | AA12: =navesOri!S12 | AB12: =naves!I12 -> 0 | AC12: =navesOri!Q12 -> 2 Twin Laser Cannons and 3 Laser Cannon Turrets. | AD12: =naves!J12 -> 0 | AE12: =naves!K12 -> 0 | AF12: =naves!L12 -> 0 | AG12: =naves!M12 -> 0
A13: =navesOri!A13 -> Gamma Class XM-1 Missile Boat | B13: =navesOri!B13 -> Other Starfighters | C13: =naves!BR13 -> Other Starfighters | D13: =navesOri!C13 -> Gamma Class XM-1 Mark 1 and Mark 2 Missile Boat | E13: =navesOri!D13 -> Cygnus Spaceworks | F13: =naves!A13 -> 3 | G13: =navesOri!E13 -> 15 meters | H13: =naves!B13 -> 15 | I13: =navesOri!F13 -> 1 | J13: =navesOri!G13 -> 40 kilograms | K13: =naves!C13 -> 40 | L13: =navesOri!H13 -> 1 week | M13: =navesOri!I13 -> x1 | N13: =naves!D13 -> 1 | O13: =navesOri!J13 | P13: =navesOri!K13 -> 122 MGLT (Speed doubles when SLAM system is used) | Q13: =naves!E13 -> 122 | R13: =navesOri!L13 -> 19 RU | S13: =naves!F13 -> 19 | T13: =navesOri!M13 -> Sub-Light Acceleration Motor (SLAM System). | U13: =naves!G13 -> 1 | V13: =navesOri!N13 -> http://insd.swcombine.com/insd/xmmiss.htm | W13: =navesOri!O13 -> http://insd.swcombine.com/insd/Ship_files/MISSILE2.JPG | X13: =navesOri!P13 -> 120 SBD | Y13: =naves!H13 -> 120 | Z13: =navesOri!R13 | AA13: =navesOri!S13 | AB13: =naves!I13 -> 0 | AC13: =navesOri!Q13 -> 1 Laser Cannon, 2 Concussion Missile Launchers (20 missiles each) and 2 General Purpose Launchers. | AD13: =naves!J13 -> 1 | AE13: =naves!K13 -> 0 | AF13: =naves!L13 -> 2 | AG13: =naves!M13 -> 2
... A110: =navesOri!A110 | B110: =navesOri!B110 | C110: =naves!BR110 -> Shuttles | D110: =navesOri!C110 | E110: =navesOri!D110 | F110: =naves!A110 -> 4 | G110: =navesOri!E110 | H110: =naves!B110 -> 20 | I110: =navesOri!F110 | J110: =navesOri!G110 | K110: =naves!C110 -> 50000 | L110: =navesOri!H110 | M110: =navesOri!I110 | N110: =naves!D110 -> 2 | O110: =navesOri!J110 | P110: =navesOri!K110 | Q110: =naves!E110 -> 67 | R110: =navesOri!L110 | S110: =naves!F110 -> 25 | T110: =navesOri!M110 | U110: =naves!G110 -> 1 | V110: =navesOri!N110 | W110: =navesOri!O110 | X110: =navesOri!P110 | Y110: =naves!H110 -> 120 | Z110: =navesOri!R110 | AA110: =navesOri!S110 | AB110: =naves!I110 -> 0 | AC110: =navesOri!Q110 | AD110: =naves!J110 -> 0 | AE110: =naves!K110 -> 0 | AF110: =naves!L110 -> 0 | AG110: =naves!M110 -> 0
A111: =navesOri!A110 | B111: =navesOri!B110 | C111: =naves!BR111 | D111: =navesOri!C110 | E111: =navesOri!D110 | F111: =naves!A111 | G111: =navesOri!E110 | H111: =naves!B111 | I111: =navesOri!F110 | J111: =navesOri!G110 | K111: =naves!C111 | L111: =navesOri!H110 | M111: =navesOri!I110 | N111: =naves!D111 | O111: =navesOri!J110 | P111: =navesOri!K110 | Q111: =naves!E111 | R111: =navesOri!L110 | S111: =naves!F111 | T111: =navesOri!M110 | U111: =naves!G111 | V111: =navesOri!N110 | W111: =navesOri!O110 | X111: =navesOri!P110 | Y111: =naves!H111 | Z111: =navesOri!R110 | AA111: =navesOri!S110 | AB111: =naves!I111 | AC111: =navesOri!Q110 | AD111: =naves!J111 | AE111: =naves!K111 | AF111: =naves!L111 | AG111: =naves!M111
A112: =navesOri!A111 | B112: =navesOri!B111 | C112: =naves!BR112 | D112: =navesOri!C111 | E112: =navesOri!D111 | F112: =naves!A112 | G112: =navesOri!E111 | H112: =naves!B112 | I112: =navesOri!F111 | J112: =navesOri!G111 | K112: =naves!C112 | L112: =navesOri!H111 | M112: =navesOri!I111 | N112: =naves!D112 | O112: =navesOri!J111 | P112: =navesOri!K111 | Q112: =naves!E112 | R112: =navesOri!L111 | S112: =naves!F112 | T112: =navesOri!M111 | U112: =naves!G112 | V112: =navesOri!N111 | W112: =navesOri!O111 | X112: =navesOri!P111 | Y112: =naves!H112 | Z112: =navesOri!R111 | AA112: =navesOri!S111 | AB112: =naves!I112 | AC112: =navesOri!Q111 | AD112: =naves!J112 | AE112: =naves!K112 | AF112: =naves!L112 | AG112: =naves!M112
A113: =navesOri!A112 | B113: =navesOri!B112 | C113: =naves!BR113 | D113: =navesOri!C112 | E113: =navesOri!D112 | F113: =naves!A113 | G113: =navesOri!E112 | H113: =naves!B113 | I113: =navesOri!F112 | J113: =navesOri!G112 | K113: =naves!C113 | L113: =navesOri!H112 | M113: =navesOri!I112 | N113: =naves!D113 | O113: =navesOri!J112 | P113: =navesOri!K112 | Q113: =naves!E113 | R113: =navesOri!L112 | S113: =naves!F113 | T113: =navesOri!M112 | U113: =naves!G113 | V113: =navesOri!N112 | W113: =navesOri!O112 | X113: =navesOri!P112 | Y113: =naves!H113 | Z113: =navesOri!R112 | AA113: =navesOri!S112 | AB113: =naves!I113 | AC113: =navesOri!Q112 | AD113: =naves!J113 | AE113: =naves!K113 | AF113: =naves!L113 | AG113: =naves!M113
A114: =navesOri!A113 | B114: =navesOri!B113 | C114: =naves!BR114 | D114: =navesOri!C113 | E114: =navesOri!D113 | F114: =naves!A114 | G114: =navesOri!E113 | H114: =naves!B114 | I114: =navesOri!F113 | J114: =navesOri!G113 | K114: =naves!C114 | L114: =navesOri!H113 | M114: =navesOri!I113 | N114: =naves!D114 | O114: =navesOri!J113 | P114: =navesOri!K113 | Q114: =naves!E114 | R114: =navesOri!L113 | S114: =naves!F114 | T114: =navesOri!M113 | U114: =naves!G114 | V114: =navesOri!N113 | W114: =navesOri!O113 | X114: =navesOri!P113 | Y114: =naves!H114 | Z114: =navesOri!R113 | AA114: =navesOri!S113 | AB114: =naves!I114 | AC114: =navesOri!Q113 | AD114: =naves!J114 | AE114: =naves!K114 | AF114: =naves!L114 | AG114: =naves!M114
A115: =navesOri!A114 | B115: =navesOri!B114 | C115: =naves!BR115 | D115: =navesOri!C114 | E115: =navesOri!D114 | F115: =naves!A115 | G115: =navesOri!E114 | H115: =naves!B115 | I115: =navesOri!F114 | J115: =navesOri!G114 | K115: =naves!C115 | L115: =navesOri!H114 | M115: =navesOri!I114 | N115: =naves!D115 | O115: =navesOri!J114 | P115: =navesOri!K114 | Q115: =naves!E115 | R115: =navesOri!L114 | S115: =naves!F115 | T115: =navesOri!M114 | U115: =naves!G115 | V115: =navesOri!N114 | W115: =navesOri!O114 | X115: =navesOri!P114 | Y115: =naves!H115 | Z115: =navesOri!R114 | AA115: =navesOri!S114 | AB115: =naves!I115 | AC115: =navesOri!Q114 | AD115: =naves!J115 | AE115: =naves!K115 | AF115: =naves!L115 | AG115: =naves!M115
A116: =navesOri!A115 | B116: =navesOri!B115 | C116: =naves!BR116 | D116: =navesOri!C115 | E116: =navesOri!D115 | F116: =naves!A116 | G116: =navesOri!E115 | H116: =naves!B116 | I116: =navesOri!F115 | J116: =navesOri!G115 | K116: =naves!C116 | L116: =navesOri!H115 | M116: =navesOri!I115 | N116: =naves!D116 | O116: =navesOri!J115 | P116: =navesOri!K115 | Q116: =naves!E116 | R116: =navesOri!L115 | S116: =naves!F116 | T116: =navesOri!M115 | U116: =naves!G116 | V116: =navesOri!N115 | W116: =navesOri!O115 | X116: =navesOri!P115 | Y116: =naves!H116 | Z116: =navesOri!R115 | AA116: =navesOri!S115 | AB116: =naves!I116 | AC116: =navesOri!Q115 | AD116: =naves!J116 | AE116: =naves!K116 | AF116: =naves!L116 | AG116: =naves!M116
A117: =navesOri!A116 | B117: =navesOri!B116 | C117: =naves!BR117 | D117: =navesOri!C116 | E117: =navesOri!D116 | F117: =naves!A117 | G117: =navesOri!E116 | H117: =naves!B117 | I117: =navesOri!F116 | J117: =navesOri!G116 | K117: =naves!C117 | L117: =navesOri!H116 | M117: =navesOri!I116 | N117: =naves!D117 | O117: =navesOri!J116 | P117: =navesOri!K116 | Q117: =naves!E117 | R117: =navesOri!L116 | S117: =naves!F117 | T117: =navesOri!M116 | U117: =naves!G117 | V117: =navesOri!N116 | W117: =navesOri!O116 | X117: =navesOri!P116 | Y117: =naves!H117 | Z117: =navesOri!R116 | AA117: =navesOri!S116 | AB117: =naves!I117 | AC117: =navesOri!Q116 | AD117: =naves!J117 | AE117: =naves!K117 | AF117: =naves!L117 | AG117: =naves!M117
A118: =navesOri!A117 | B118: =navesOri!B117 | C118: =naves!BR118 | D118: =navesOri!C117 | E118: =navesOri!D117 | F118: =naves!A118 | G118: =navesOri!E117 | H118: =naves!B118 | I118: =navesOri!F117 | J118: =navesOri!G117 | K118: =naves!C118 | L118: =navesOri!H117 | M118: =navesOri!I117 | N118: =naves!D118 | O118: =navesOri!J117 | P118: =navesOri!K117 | Q118: =naves!E118 | R118: =navesOri!L117 | S118: =naves!F118 | T118: =navesOri!M117 | U118: =naves!G118 | V118: =navesOri!N117 | W118: =navesOri!O117 | X118: =navesOri!P117 | Y118: =naves!H118 | Z118: =navesOri!R117 | AA118: =navesOri!S117 | AB118: =naves!I118 | AC118: =navesOri!Q117 | AD118: =naves!J118 | AE118: =naves!K118 | AF118: =naves!L118 | AG118: =naves!M118
A119: =navesOri!A118 | B119: =navesOri!B118 | C119: =naves!BR119 | D119: =navesOri!C118 | E119: =navesOri!D118 | F119: =naves!A119 | G119: =navesOri!E118 | H119: =naves!B119 | I119: =navesOri!F118 | J119: =navesOri!G118 | K119: =naves!C119 | L119: =navesOri!H118 | M119: =navesOri!I118 | N119: =naves!D119 | O119: =navesOri!J118 | P119: =navesOri!K118 | Q119: =naves!E119 | R119: =navesOri!L118 | S119: =naves!F119 | T119: =navesOri!M118 | U119: =naves!G119 | V119: =navesOri!N118 | W119: =navesOri!O118 | X119: =navesOri!P118 | Y119: =naves!H119 | Z119: =navesOri!R118 | AA119: =navesOri!S118 | AB119: =naves!I119 | AC119: =navesOri!Q118 | AD119: =naves!J119 | AE119: =naves!K119 | AF119: =naves!L119 | AG119: =naves!M119
A120: =navesOri!A119 | B120: =navesOri!B119 | C120: =naves!BR120 | D120: =navesOri!C119 | E120: =navesOri!D119 | F120: =naves!A120 | G120: =navesOri!E119 | H120: =naves!B120 | I120: =navesOri!F119 | J120: =navesOri!G119 | K120: =naves!C120 | L120: =navesOri!H119 | M120: =navesOri!I119 | N120: =naves!D120 | O120: =navesOri!J119 | P120: =navesOri!K119 | Q120: =naves!E120 | R120: =navesOri!L119 | S120: =naves!F120 | T120: =navesOri!M119 | U120: =naves!G120 | V120: =navesOri!N119 | W120: =navesOri!O119 | X120: =navesOri!P119 | Y120: =naves!H120 | Z120: =navesOri!R119 | AA120: =navesOri!S119 | AB120: =naves!I120 | AC120: =navesOri!Q119 | AD120: =naves!J120 | AE120: =naves!K120 | AF120: =naves!L120 | AG120: =naves!M120
A121: =navesOri!A120 | B121: =navesOri!B120 | C121: =naves!BR121 | D121: =navesOri!C120 | E121: =navesOri!D120 | F121: =naves!A121 | G121: =navesOri!E120 | H121: =naves!B121 | I121: =navesOri!F120 | J121: =navesOri!G120 | K121: =naves!C121 | L121: =navesOri!H120 | M121: =navesOri!I120 | N121: =naves!D121 | O121: =navesOri!J120 | P121: =navesOri!K120 | Q121: =naves!E121 | R121: =navesOri!L120 | S121: =naves!F121 | T121: =navesOri!M120 | U121: =naves!G121 | V121: =navesOri!N120 | W121: =navesOri!O120 | X121: =navesOri!P120 | Y121: =naves!H121 | Z121: =navesOri!R120 | AA121: =navesOri!S120 | AB121: =naves!I121 | AC121: =navesOri!Q120 | AD121: =naves!J121 | AE121: =naves!K121 | AF121: =naves!L121 | AG121: =naves!M121
A122: =navesOri!A121 | B122: =navesOri!B121 | C122: =naves!BR122 | D122: =navesOri!C121 | E122: =navesOri!D121 | F122: =naves!A122 | G122: =navesOri!E121 | H122: =naves!B122 | I122: =navesOri!F121 | J122: =navesOri!G121 | K122: =naves!C122 | L122: =navesOri!H121 | M122: =navesOri!I121 | N122: =naves!D122 | O122: =navesOri!J121 | P122: =navesOri!K121 | Q122: =naves!E122 | R122: =navesOri!L121 | S122: =naves!F122 | T122: =navesOri!M121 | U122: =naves!G122 | V122: =navesOri!N121 | W122: =navesOri!O121 | X122: =navesOri!P121 | Y122: =naves!H122 | Z122: =navesOri!R121 | AA122: =navesOri!S121 | AB122: =naves!I122 | AC122: =navesOri!Q121 | AD122: =naves!J122 | AE122: =naves!K122 | AF122: =naves!L122 | AG122: =naves!M122
... A142: =navesOri!A141 | B142: =navesOri!B141 | C142: =naves!BR142 | D142: =navesOri!C141 | E142: =navesOri!D141 | F142: =naves!A142 | G142: =navesOri!E141 | H142: =naves!B142 | I142: =navesOri!F141 | J142: =navesOri!G141 | K142: =naves!C142 | L142: =navesOri!H141 | M142: =navesOri!I141 | N142: =naves!D142 | O142: =navesOri!J141 | P142: =navesOri!K141 | Q142: =naves!E142 | R142: =navesOri!L141 | S142: =naves!F142 | T142: =navesOri!M141 | U142: =naves!G142 | V142: =navesOri!N141 | W142: =navesOri!O141 | X142: =navesOri!P141 | Y142: =naves!H142 | Z142: =navesOri!R141 | AA142: =navesOri!S141 | AB142: =naves!I142 | AC142: =navesOri!Q141 | AD142: =naves!J142 | AE142: =naves!K142 | AF142: =naves!L142 | AG142: =naves!M142
